Workbook

Sheet Overall
B1: Overall Summary (Daily) | G1: Date: | I1: =TODAY() -> 46149
B2: Collection | G2: Registration
B3: =CONCATENATE("₹ ",ROUND($N$27,2)," / ",ROUND($M$27,2)," (",ROUND($O$27,3)*100,"%)") -> ₹ 28.43 / 47.09 (60.4%) | E3: =CONCATENATE("₹ ",ROUND($N$11,2), " | ", "₹ ",ROUND($O$11,2)) -> ₹ 0 | ₹ 28.88 | G3: =CONCATENATE($U$11, " | ", $T$11) -> 25 | 35 | L3: Projects | M3: Total Live Bookings | N3: Daily Collection (In Cr) | O3: Monthly Collection (In Cr) | P3: Monthly Registrations | Q3: Actual Demand Raised (In Cr) till date | R3: Collection (In Cr) till date | S3: Outstanding (In Cr) till date | T3: Pending Registrations | U3: Pending Registrations (> 45 days) | V3: Registration Targets | W3: Outstanding (In Cr) till date | X3: Registration Targets < 20th of the month
B4: Monthly Collection (In Cr) | E4: Daily | Monthly Collection (In Cr) (Includes Booking Amount) | G4: Pending Registrations | L4: RAGHAV Paradise | M4: ='[1]Project Summary'!$B$7 -> 187 | N4: ='[1]Project Summary'!$D$7 -> 0 | O4: ='[1]Project Summary'!$E$7 -> 4.4807139 | P4: ='[1]Project Summary'!$F$7 -> 1 | Q4: ='[1]Project Summary'!$C$14 -> 206.69615 | R4: ='[1]Project Summary'!$D$14 -> 205.64925 | S4: ='[1]Project Summary'!$E$14 -> 3.6806382 | T4: ='[1]Project Summary'!$D$21 -> 1 | U4: ='[1]Project Summary'!$F$21 -> 1 | V4: ='[1]Project Summary'!$Q$3 -> 0 | W4: 11.947645 | X4: ='[1]Project Summary'!$R$3 -> 0
L5: RAGHAV Parijat | M5: ='[2]Project Summary'!$B$7 -> 105 | N5: ='[2]Project Summary'!$D$7 -> 0 | O5: ='[2]Project Summary'!$E$7 -> 8.650219 | P5: ='[2]Project Summary'!$F$7 -> 0 | Q5: ='[2]Project Summary'!$C$13 -> 101.85286 | R5: ='[2]Project Summary'!$D$13 -> 96.866328 | S5: ='[2]Project Summary'!$E$13 -> 5.9417039 | T5: ='[2]Project Summary'!$D$20 -> 1 | U5: ='[2]Project Summary'!$F$20 -> 1 | V5: ='[2]Project Summary'!$Q$3 -> 1 | W5: 2.0392637 | X5: ='[2]Project Summary'!$R$3 -> 0 | Y5: ='[2]Project Summary'!$R$3 -> 0
B6: =$S$11 -> 16.644024 | E6: =P27 -> 22.79 | G6: =CONCATENATE($P$11," / ",V11) -> 16 / 25 | L6: RAGHAV ANANTA | M6: ='[3]Project Summary'!$B$7 -> 74 | N6: ='[3]Project Summary'!$D$7 -> 0 | O6: ='[3]Project Summary'!$E$7 -> 5.3060298 | P6: ='[3]Project Summary'!$F$7 -> 4 | Q6: ='[3]Project Summary'!$C$13 -> 45.568175 | R6: ='[3]Project Summary'!$D$13 -> 46.860069 | S6: ='[3]Project Summary'!$E$13 -> 1.615276 | T6: ='[3]Project Summary'!$D$20 -> 15 | U6: ='[3]Project Summary'!$F$20 -> 10 | V6: ='[3]Project Summary'!$Q$3 -> 10 | W6: 1.4527025 | X6: ='[3]Project Summary'!$R$3 -> 8
B7: Outstanding (In Cr) as of today | E7: CRM Forecast - Feb (In Cr.) | G7: Monthly Registrations Targets | L7: RAGHAV Vista | M7: ='[4]Project Summary'!$B$7 -> 50 | N7: ='[4]Project Summary'!$D$7 -> 0 | O7: ='[4]Project Summary'!$E$7 -> 3.9736441 | P7: ='[4]Project Summary'!$F$7 -> 4 | Q7: ='[4]Project Summary'!$C$13 -> 33.941633 | R7: ='[4]Project Summary'!$D$13 -> 33.694863 | S7: ='[4]Project Summary'!$E$13 -> 0.5885487 | T7: ='[4]Project Summary'!$D$20 -> 3 | U7: ='[4]Project Summary'!$F$20 -> 1 | V7: ='[4]Project Summary'!$Q$3 -> 7 | W7: 2.5358006 | X7: ='[4]Project Summary'!$R$3 -> 6
L8: RAGHAV Avenue | M8: ='[5]Project Summary'!$B$7 -> 54 | N8: ='[5]Project Summary'!$D$7 -> 0 | O8: ='[5]Project Summary'!$E$7 -> 4.2654046 | P8: ='[5]Project Summary'!$F$7 -> 7 | Q8: ='[5]Project Summary'!$C$13 -> 23.986368 | R8: ='[5]Project Summary'!$D$13 -> 24.688711 | S8: ='[5]Project Summary'!$E$13 -> 2.6275068 | T8: ='[5]Project Summary'!$D$20 -> 11 | U8: ='[5]Project Summary'!$F$20 -> 8 | V8: ='[5]Project Summary'!$Q$3 -> 6 | X8: ='[5]Project Summary'!$R$3 -> 6
L9: RAGHAV Marvel | M9: ='[8]Project Summary'!$B$7 -> 94 | N9: ='[8]Project Summary'!$D$7 -> 0 | O9: ='[8]Project Summary'!$E$7 -> 0 | P9: ='[8]Project Summary'!$F$7 -> 0 | Q9: ='[8]Project Summary'!$C$13 -> 78.586592 | R9: ='[8]Project Summary'!$D$13 -> 78.357737 | S9: ='[8]Project Summary'!$E$13 -> 0.2288555 | T9: ='[8]Project Summary'!$D$20 -> 1 | U9: ='[8]Project Summary'!$F$20 -> 1 | V9: ='[8]Project Summary'!$Q$3 -> 0 | W9: 2.3999062 | X9: ='[8]Project Summary'!$R$3 -> 0
L10: RAGHAV Enclave | M10: ='[7]Project Summary'!$B$7 -> 24 | N10: ='[7]Project Summary'!$D$7 -> 0 | O10: ='[7]Project Summary'!$E$7 -> 2.205519 | P10: ='[7]Project Summary'!$F$7 -> 0 | Q10: ='[7]Project Summary'!$C$13 -> 19.816488 | R10: ='[7]Project Summary'!$D$13 -> 18.298131 | S10: ='[7]Project Summary'!$E$13 -> 1.961495 | T10: ='[7]Project Summary'!$D$20 -> 3 | U10: ='[7]Project Summary'!$F$20 -> 3 | V10: ='[7]Project Summary'!$Q$3 -> 1 | W10: 2.3999062 | X10: ='[7]Project Summary'!$R$3 -> 1
L11: Total | M11: =SUM(M4:M10) -> 588 | N11: =SUM(N4:N10) -> 0 | O11: =SUM(O4:O10) -> 28.88153 | P11: =SUM(P4:P10) -> 16 | Q11: =SUM(Q4:Q10) -> 510.44826 | R11: =SUM(R4:R10) -> 504.41509 | S11: =SUM(S4:S10) -> 16.644024 | T11: =SUM(T4:T10) -> 35 | ... X11: =SUM(X4:X10) -> 21
L18: Project wise: Target vs Achievement Status | S18: Category wise: Target vs Achievement Status
L19: Project | M19: Target | N19: Achievement | O19: Achievement % | P19: Forecast as per CRM | S19: TARGET CATEGORY | T19: Target | U19: Achievement | V19: Achievement % | W19: Forecast as per CRM | X19: Balance
L20: RAGHAV Paradise | M20: ='[1]Project Summary'!$I$13 -> 6.2309036 | N20: ='[1]Project Summary'!$J$13 -> 4.4100472 | O20: =N20/M20 -> 0.70777009 | P20: ='[1]Project Summary'!$L$13 -> 2.24 | Q20: =M20-N20 -> 1.8208564 | S20: Spill Over | T20: =M43 -> 13.627007 | U20: =N43 -> 7.0392804 | V20: =O43 -> 0.51656834 | W20: =P43 -> 7.24 | X20: =T20-W20 -> 6.3870072
L21: RAGHAV Parijat | M21: ='[2]Project Summary'!$I$13 -> 14.267345 | N21: ='[2]Project Summary'!$J$13 -> 8.650219 | O21: =N21/M21 -> 0.60629492 | P21: ='[2]Project Summary'!$L$13 -> 0.68 | Q21: =M21-N21 -> 5.6171262 | S21: Own Contribution (OCR) - Unregistered | T21: =Q43 -> 1.9380641 | U21: =R43 -> 0.90137076 | V21: =S43 -> 0.46508821 | W21: =T43 -> 0.2 | X21: =T21-W21 -> 1.7380641
L22: RAGHAV ANANTA | M22: ='[3]Project Summary'!$I$13 -> 8.5662665 | N22: ='[3]Project Summary'!$J$13 -> 5.0352061 | O22: =N22/M22 -> 0.5877947 | P22: ='[3]Project Summary'!$L$13 -> 6.35 | Q22: =M22-N22 -> 3.5310604 | S22: OCR - New Bookings | T22: =U43 -> 0 | U22: =V43 -> 0.36691962 | V22: =W43 -> #DIV/0! | W22: =X43 -> 0 | X22: =T22-W22 -> 0
L23: RAGHAV Vista | M23: ='[4]Project Summary'!$I$13 -> 7.770897 | N23: ='[4]Project Summary'!$J$13 -> 3.9198345 | O23: =N23/M23 -> 0.50442497 | P23: ='[4]Project Summary'!$L$13 -> 5.05 | Q23: =M23-N23 -> 3.8510625 | S23: =CONCATENATE("Demand For Registrations post 20th of last month") -> Demand For Registrations post 20th of last month | T23: =Y43 -> 5.4110873 | U23: =Z43 -> 5.5059146 | V23: =AA43 -> 1.0175246 | W23: =AB43 -> 5.41 | X23: =T23-W23 -> 0.0010873
L24: RAGHAV Avenue | M24: ='[5]Project Summary'!$I$13 -> 5.5341277 | N24: ='[5]Project Summary'!$J$13 -> 4.2083467 | O24: =N24/M24 -> 0.76043541 | P24: ='[5]Project Summary'!$L$13 -> 4.17 | Q24: =P24-3.01 -> 1.16 | S24: =CONCATENATE("Expected New Monthly Registrations") -> Expected New Monthly Registrations | T24: =AC43 -> 13.69 | U24: =AD43 -> 6.7300527 | V24: =AE43 -> 0.49160356 | W24: =AF43 -> 9.37 | X24: =T24-W24 -> 4.32
L25: RAGHAV Marvel | M25: ='[8]Project Summary'!$I$13 -> 0.23 | N25: ='[8]Project Summary'!$J$13 -> 0 | O25: =N25/M25 -> 0 | P25: ='[8]Project Summary'!$L$13 -> 0 | Q25: =M25-N25 -> 0.23 | S25: New Slab / New Demand | T25: =AG43 -> 12.42 | U25: =AH43 -> 8.2525539 | V25: =AI43 -> 0.66445684 | W25: =AJ43 -> 0.57 | X25: =T25-W25 -> 11.85
L26: RAGHAV Enclave | M26: ='[7]Project Summary'!$I$13 -> 4.4866186 | N26: ='[7]Project Summary'!$J$13 -> 2.205519 | O26: ='[7]Project Summary'!$K$13 -> 0.49157712 | P26: ='[7]Project Summary'!$L$13 -> 4.3 | Q26: =M26-N26 -> 2.2810996
L27: Overall | M27: =SUM(M20:M26) -> 47.086159 | N27: =SUM(N20:N26) -> 28.429172 | O27: =N27/M27 -> 0.6037692 | P27: =SUM(P20:P26) -> 22.79 | Q27: =M27-N27 -> 18.656986
M34: Spill Over from Registered Bookings | Q34: OCR - Unregistered Bookings | U34: =CONCATENATE("OCR - Expected New Bookings in"," Sept") -> OCR - Expected New Bookings in Sept | Y34: =CONCATENATE("Demand Raised for Registrations after ","20 April 2024") -> Demand Raised for Registrations after 20 April 2024 | AC34: =CONCATENATE("Expected Registrations in August ",$D$3,"'",$E$3," ") -> Expected Registrations in August '₹ 0 | ₹ 28.88 | AG34: Slab Amount / Possession Amt
L35: Target Headers | M35: Collection Target | N35: Collection Achievement | O35: Achievement % | P35: Forecast as per CRM | Q35: Collection Target | R35: Collection Achievement | S35: Achievement % | T35: Forecast as per CRM | U35: Collection Target | V35: Collection Achievement | W35: Achievement % | X35: Forecast as per CRM | Y35: Collection Target | Z35: Collection Achievement | AA35: Achievement % | AB35: Forecast as per CRM | AC35: Collection Target | AD35: Collection Achievement | AE35: Achievement % | AF35: Forecast as per CRM | AG35: Collection Target | AH35: Collection Achievement | AI35: Achievement % | AJ35: Forecast as per CRM
L36: Raghav Paradise | M36: ='[1]Project Summary'!$I$7 -> 6.0278847 | N36: ='[1]Project Summary'!$J$7 -> 2.5798586 | O36: =N36/M36 -> 0.42798738 | P36: ='[1]Project Summary'!$L$7 -> 2.04 | Q36: ='[1]Project Summary'!$I$8 -> 0.2030189 | R36: ='[1]Project Summary'!$J$8 -> 0 | S36: =R36/Q36 -> 0 | T36: ='[1]Project Summary'!$L$8 -> 0.2 | U36: ='[1]Project Summary'!$I$9 -> 0 | V36: ='[1]Project Summary'!$J$9 -> 0 | W36: =V36/U36 -> #DIV/0! | X36: ='[1]Project Summary'!$L$9 -> 0 | Y36: ='[1]Project Summary'!$I$10 -> 0 | Z36: ='[1]Project Summary'!$J$10 -> 0 | AA36: =Z36/Y36 -> #DIV/0! | AB36: ='[1]Project Summary'!$L$10 -> 0 | AC36: ='[1]Project Summary'!$I$11 -> 0 | AD36: ='[1]Project Summary'!$J$11 -> 1.8301886 | AE36: =AD36/AC36 -> #DIV/0! | AF36: ='[1]Project Summary'!$L$11 -> 0 | AG36: ='[1]Project Summary'!$I$12 -> 0 | AH36: ='[1]Project Summary'!$J$12 -> 0 | AI36: =AH36/AG36 -> #DIV/0! | AJ36: ='[1]Project Summary'!$L$12 -> 0
L37: Raghav Parijat | M37: ='[2]Project Summary'!$I$7 -> 2.4173452 | N37: ='[2]Project Summary'!$J$7 -> 1.1720278 | O37: =N37/M37 -> 0.48484091 | P37: ='[2]Project Summary'!$L$7 -> 0.68 | Q37: ='[2]Project Summary'!$I$8 -> 0 | R37: ='[2]Project Summary'!$J$8 -> 0 | S37: =R37/Q37 -> #DIV/0! | T37: ='[2]Project Summary'!$L$8 -> 0 | U37: ='[2]Project Summary'!$I$9 -> 0 | V37: ='[2]Project Summary'!$J$9 -> 0 | W37: =V37/U37 -> #DIV/0! | X37: ='[2]Project Summary'!$L$9 -> 0 | Y37: ='[2]Project Summary'!$I$10 -> 0 | Z37: ='[2]Project Summary'!$J$10 -> 0 | AA37: =Z37/Y37 -> #DIV/0! | AB37: ='[2]Project Summary'!$L$10 -> 0 | AC37: ='[2]Project Summary'!$I$11 -> 0 | AD37: ='[2]Project Summary'!$J$11 -> 0 | AE37: =AD37/AC37 -> #DIV/0! | AF37: ='[2]Project Summary'!$L$11 -> 0 | AG37: ='[2]Project Summary'!$I$12 -> 11.85 | AH37: ='[2]Project Summary'!$J$12 -> 7.4781911 | AI37: =AH37/AG37 -> 0.63107098 | AJ37: ='[2]Project Summary'!$L$12 -> 0 | AK37: =AJ37/AG37 -> 0
L38: RAGHAV ANANTA | M38: ='[3]Project Summary'!$I$7 -> 2.2269664 | N38: ='[3]Project Summary'!$J$7 -> 1.6921175 | O38: =N38/M38 -> 0.75983072 | P38: ='[3]Project Summary'!$L$7 -> 2.08 | Q38: ='[3]Project Summary'!$I$8 -> 0.4893001 | R38: ='[3]Project Summary'!$J$8 -> 0.51428571 | S38: =R38/Q38 -> 1.051064 | T38: ='[3]Project Summary'!$L$8 -> 0 | U38: ='[3]Project Summary'!$I$9 -> 0 | V38: ='[3]Project Summary'!$J$9 -> 0.31844276 | W38: =V38/U38 -> #DIV/0! | X38: ='[3]Project Summary'!$L$9 -> 0 | Y38: ='[3]Project Summary'!$I$10 -> 0.39 | Z38: ='[3]Project Summary'!$J$10 -> 0.30558525 | AA38: =Z38/Y38 -> 0.78355192 | AB38: ='[3]Project Summary'!$L$10 -> 0.39 | AC38: ='[3]Project Summary'!$I$11 -> 5.46 | AD38: ='[3]Project Summary'!$J$11 -> 1.9107596 | AE38: =AD38/AC38 -> 0.34995598 | AF38: ='[3]Project Summary'!$L$11 -> 3.88 | AG38: ='[3]Project Summary'!$I$12 -> 0 | AH38: ='[3]Project Summary'!$J$12 -> 0.612458 | AI38: =AH38/AG38 -> #DIV/0! | AJ38: ='[3]Project Summary'!$L$12 -> 0
L39: Raghav Vista | M39: ='[4]Project Summary'!$I$7 -> 0.4572421 | N39: ='[4]Project Summary'!$J$7 -> 0.33286333 | O39: =N39/M39 -> 0.7279805 | P39: ='[4]Project Summary'!$L$7 -> 0.46 | Q39: ='[4]Project Summary'!$I$8 -> 0.4936549 | R39: ='[4]Project Summary'!$J$8 -> 0.035090286 | S39: =R39/Q39 -> 0.071082624 | T39: ='[4]Project Summary'!$L$8 -> 0 | U39: ='[4]Project Summary'!$I$9 -> 0 | V39: ='[4]Project Summary'!$J$9 -> 0.0094285714 | W39: =V39/U39 -> #DIV/0! | X39: ='[4]Project Summary'!$L$9 -> 0 | Y39: ='[4]Project Summary'!$I$10 -> 2.43 | Z39: ='[4]Project Summary'!$J$10 -> 2.8829241 | AA39: =Z39/Y39 -> 1.1863885 | AB39: ='[4]Project Summary'!$L$10 -> 2.43 | AC39: ='[4]Project Summary'!$I$11 -> 4.11 | AD39: ='[4]Project Summary'!$J$11 -> 0.507052 | AE39: =AD39/AC39 -> 0.12337032 | AF39: ='[4]Project Summary'!$L$11 -> 1.88 | AG39: ='[4]Project Summary'!$I$12 -> 0.28 | AH39: ='[4]Project Summary'!$J$12 -> 0.16190476 | AI39: =AH39/AG39 -> 0.57823129 | AJ39: ='[4]Project Summary'!$L$12 -> 0.28
L40: RAGHAV Avenue | M40: ='[5]Project Summary'!$I$7 -> 0.4509504 | N40: ='[5]Project Summary'!$J$7 -> 0.7862227 | O40: =N40/M40 -> 1.7434793 | P40: ='[5]Project Summary'!$L$7 -> 0.16 | Q40: ='[5]Project Summary'!$I$8 -> 0.5620902 | R40: ='[5]Project Summary'!$J$8 -> 0.16809524 | S40: =R40/Q40 -> 0.29905385 | T40: ='[5]Project Summary'!$L$8 -> 0 | U40: ='[5]Project Summary'!$I$9 -> 0 | V40: ='[5]Project Summary'!$J$9 -> 0.039048286 | W40: =V40/U40 -> #DIV/0! | X40: ='[5]Project Summary'!$L$9 -> 0 | Y40: ='[5]Project Summary'!$I$10 -> 1.4410871 | Z40: ='[5]Project Summary'!$J$10 -> 0.77197622 | AA40: =Z40/Y40 -> 0.53569019 | AB40: ='[5]Project Summary'!$L$10 -> 1.44 | AC40: ='[5]Project Summary'!$I$11 -> 2.79 | AD40: ='[5]Project Summary'!$J$11 -> 2.4820525 | AE40: =AD40/AC40 -> 0.88962455 | AF40: ='[5]Project Summary'!$L$11 -> 2.28 | AG40: ='[5]Project Summary'!$I$12 -> 0.29 | AH40: ='[5]Project Summary'!$J$12 -> 0 | AI40: =AH40/AG40 -> 0 | AJ40: ='[5]Project Summary'!$L$12 -> 0.29
L41: Raghav Marvel | M41: ='[8]Project Summary'!$I$7 -> 0.23 | N41: ='[8]Project Summary'!$J$7 -> 0 | O41: =N41/M41 -> 0 | P41: ='[8]Project Summary'!$L$7 -> 0 | Q41: ='[8]Project Summary'!$I$8 -> 0 | R41: ='[8]Project Summary'!$J$8 -> 0 | S41: =R41/Q41 -> #DIV/0! | T41: ='[8]Project Summary'!$L$8 -> 0 | U41: ='[8]Project Summary'!$I$9 -> 0 | V41: ='[8]Project Summary'!$J$9 -> 0 | W41: =V41/U41 -> #DIV/0! | X41: ='[8]Project Summary'!$L$9 -> 0 | Y41: ='[8]Project Summary'!$I$10 -> 0 | Z41: ='[8]Project Summary'!$J$10 -> 0 | AA41: =Z41/Y41 -> #DIV/0! | AB41: ='[8]Project Summary'!$L$10 -> 0 | AC41: ='[8]Project Summary'!$I$11 -> 0 | AD41: ='[8]Project Summary'!$J$11 -> 0 | AE41: =AD41/AC41 -> #DIV/0! | AF41: ='[8]Project Summary'!$L$11 -> 0 | AG41: ='[8]Project Summary'!$I$12 -> 0 | AH41: ='[8]Project Summary'!$J$12 -> 0 | AI41: =AH41/AG41 -> #DIV/0! | AJ41: ='[8]Project Summary'!$L$12 -> 0
L42: Raghav Enclave | M42: ='[7]Project Summary'!$I$7 -> 1.8166184 | N42: ='[7]Project Summary'!$J$7 -> 0.47619048 | O42: =N42/M42 -> 0.26213016 | P42: ='[7]Project Summary'!$L$7 -> 1.82 | Q42: ='[7]Project Summary'!$I$8 -> 0.19 | R42: ='[7]Project Summary'!$J$8 -> 0.18389952 | S42: =R42/Q42 -> 0.96789223 | T42: ='[7]Project Summary'!$L$8 -> 0 | U42: ='[7]Project Summary'!$I$9 -> 0 | V42: ='[7]Project Summary'!$J$9 -> 0 | W42: =V42/U42 -> #DIV/0! | X42: ='[7]Project Summary'!$L$9 -> 0 | Y42: ='[7]Project Summary'!$I$10 -> 1.1500002 | Z42: ='[7]Project Summary'!$J$10 -> 1.545429 | AA42: =Z42/Y42 -> 1.3438511 | AB42: ='[7]Project Summary'!$L$10 -> 1.15 | AC42: ='[7]Project Summary'!$I$11 -> 1.33 | AD42: ='[7]Project Summary'!$J$11 -> 0 | AE42: =AD42/AC42 -> 0 | AF42: ='[7]Project Summary'!$L$11 -> 1.33 | AG42: ='[7]Project Summary'!$I$12 -> 0 | AH42: ='[7]Project Summary'!$J$12 -> 0 | AI42: =AH42/AG42 -> #DIV/0! | AJ42: ='[7]Project Summary'!$L$12 -> 0
L43: Overall | M43: =SUM(M36:M42) -> 13.627007 | N43: =SUM(N36:N42) -> 7.0392804 | O43: =N43/M43 -> 0.51656834 | P43: =SUM(P36:P42) -> 7.24 | Q43: =SUM(Q36:Q42) -> 1.9380641 | R43: =SUM(R36:R42) -> 0.90137076 | S43: =R43/Q43 -> 0.46508821 | T43: =SUM(T36:T42) -> 0.2 | U43: =SUM(U36:U42) -> 0 | V43: =SUM(V36:V42) -> 0.36691962 | W43: =V43/U43 -> #DIV/0! | X43: =SUM(X36:X42) -> 0 | Y43: =SUM(Y36:Y42) -> 5.4110873 | Z43: =SUM(Z36:Z42) -> 5.5059146 | AA43: =Z43/Y43 -> 1.0175246 | AB43: =SUM(AB36:AB42) -> 5.41 | AC43: =SUM(AC36:AC42) -> 13.69 | AD43: =SUM(AD36:AD42) -> 6.7300527 | AE43: =AD43/AC43 -> 0.49160356 | AF43: =SUM(AF36:AF42) -> 9.37 | AG43: =SUM(AG36:AG42) -> 12.42 | AH43: =SUM(AH36:AH42) -> 8.2525539 | AI43: =AH43/AG43 -> 0.66445684 | AJ43: =SUM(AJ36:AJ42) -> 0.57
Q45: =M27-Q43 -> 45.148094 | R45: =N27-R43 -> 27.527802
L52: Weekly Forecast | V52: Headers | W52: Raghav Paradise | X52: Raghav Parijat | Y52: RAGHAV ANANTA | Z52: Raghav Vista | AA52: RAGHAV Avenue | AB52: Raghav Marvel | AC52: Raghav Enclave | AD52: Total
L53: Weekly Forecast | M53: Customer Committed Amount | N53: RAGHAV Paradise | O53: RAGHAV Parijat | P53: RAGHAV ANANTA | Q53: RAGHAV Vista | R53: RAGHAV Marvel | S53: RAGHAV Enclave | V53: Spill Over | W53: ='[1]Project Summary'!$L$18 -> 3.6806382 | X53: ='[2]Project Summary'!$L$18 -> 5.9034896 | Y53: ='[3]Project Summary'!$L$18 -> 0.48546493 | Z53: ='[4]Project Summary'!$L$18 -> 0.24255796 | AA53: ='[5]Project Summary'!$L$18 -> 0.2919116 | AB53: 0.23 | AC53: ='[7]Project Summary'!$L$18 -> 1.5309041 | AD53: =SUM(W53:AC53) -> 12.364966
L54: Week 1 | M54: =SUM(N54:R54) -> 1.1717345 | N54: ='[1]Project Summary'!$I$18 -> 1.1717345 | V54: Own Contribution (OCR) - Unregistered | W54: ='[1]Project Summary'!$L$19 -> 0 | X54: ='[2]Project Summary'!$L$19 -> 0.0382143 | Y54: ='[3]Project Summary'!$L$19 -> 1e-07 | Z54: ='[4]Project Summary'!$L$19 -> 0.0885713 | AA54: ='[5]Project Summary'!$L$19 -> 0.421614 | AC54: ='[7]Project Summary'!$L$19 -> 0.41800528 | AD54: =SUM(W54:AC54) -> 0.96640498
L55: Week 2 | M55: =SUM(N55:R55) -> 2.2479263 | N55: ='[1]Project Summary'!$I$19 -> 2.2479263 | V55: OCR - New Bookings | W55: ='[1]Project Summary'!$L$20 -> 0 | X55: ='[2]Project Summary'!$L$20 -> 0 | Y55: ='[3]Project Summary'!$L$20 -> 0 | Z55: ='[4]Project Summary'!$L$20 -> 0 | AA55: ='[5]Project Summary'!$L$20 -> 0.12619049 | AC55: ='[7]Project Summary'!$L$20 -> 0 | AD55: =SUM(W55:AC55) -> 0.12619049
L56: Week 3 | M56: =SUM(N56:R56) -> 0.7007274 | N56: ='[1]Project Summary'!$I$20 -> 0.7007274 | V56: =CONCATENATE("Demand For Registrations post 20th of last month") -> Demand For Registrations post 20th of last month | W56: ='[1]Project Summary'!$L$2 -> 0 | X56: ='[2]Project Summary'!$L$21 -> 0 | Y56: ='[3]Project Summary'!$L$21 -> 0.19047625 | Z56: ='[4]Project Summary'!$L$21 -> 0.20846761 | AA56: ='[5]Project Summary'!$L$21 -> 1.7596301 | AC56: ='[7]Project Summary'!$L$21 -> 0.01258561 | AD56: =SUM(W56:AC56) -> 2.1711596
L57: Week 4 | M57: =SUM(N57:R57) -> 1.4966375 | N57: ='[1]Project Summary'!$I$21 -> 1.4966375 | V57: =CONCATENATE("Expected New Monthly Registrations") -> Expected New Monthly Registrations | W57: ='[1]Project Summary'!$L$22 -> 0 | X57: ='[2]Project Summary'!$L$22 -> 0 | Y57: ='[3]Project Summary'!$L$22 -> 0.93933469 | Z57: ='[4]Project Summary'!$L$22 -> 0.048951824 | AA57: ='[5]Project Summary'!$L$22 -> 0.028160576 | AC57: ='[7]Project Summary'!$L$22 -> 0 | AD57: =SUM(W57:AC57) -> 1.0164471
L58: Week 5 | M58: =SUM(N58:R58) -> 0.0489544 | N58: ='[1]Project Summary'!$I$22 -> 0.0489544 | V58: Total | W58: =SUM(W53:W57) -> 3.6806382 | X58: =SUM(X53:X57) -> 5.9417039 | Y58: =SUM(Y53:Y57) -> 1.615276 | Z58: =SUM(Z53:Z57) -> 0.5885487 | AA58: =SUM(AA53:AA57) -> 2.6275068 | AB58: =SUM(AB53:AB57) -> 0.23 | AC58: =SUM(AC53:AC57) -> 1.961495 | AD58: =SUM(AD53:AD57) -> 16.645169
L59: Spill Over | M59: =SUM(N59:R59) -> 1.1047847 | N59: ='[1]Project Summary'!$I$23 -> 1.1047847
...

Sheet Overall - Testing
B1: Overall Summary (Daily) | H1: Date: | J1: =TODAY() -> 46149 | Q1: Project Wise Status
B2: Collection | H2: Registration
B3: =$R$19 -> 22.274085 | D3: =$T$9 -> 6.1823202 | F3: =$S$9 -> 0 | H3: =CONCATENATE($Z$9, " / ", $Y$9) -> 9 / 17 | L3: 8 | Q3: Projects | R3: Total Live Bookings | S3: Daily Collection (In Cr) | T3: Monthly Collection (In Cr) | U3: Monthly Registrations | V3: Actual Demand Raised (In Cr) till date | W3: Collection (In Cr) till date | X3: Outstanding (In Cr) till date | Y3: Pending Registrations | Z3: Pending Registrations (> 45 days) | AA3: Registration Targets
B4: Monthly CRM Targets (In Cr) | D4: Monthly Collection (In Cr) | F4: Daily Collection (In Cr) | H4: Registration Pending (> 45 Days) as of today | Q4: Raghav Paradise | R4: 171 | S4: 0 | T4: 1.8087668 | U4: 6 | V4: 154.98938 | W4: 149.81973 | X4: 6.9791362 | Y4: 12 | Z4: 4 | AA4: 7
Q5: Raghav Parijat | R5: 171 | S5: 0 | T5: 1.8087668 | U5: 6 | V5: 5.7359943 | W5: 5.5863674 | X5: 0.8322619 | Y5: 0 | Z5: Registrations Pending (> 45 Days) | AA5: 7
B6: =$X$9 -> 10.826593 | D6: =$W$19 -> 6.6640614 | F6: =$W$19 -> 6.6640614 | H6: =CONCATENATE($U$9," / ",AA9) -> 17 / 20 | Q6: Raghav Nova | R6: 112 | S6: 0 | T6: 2.3140931 | U6: 3 | V6: 48.703445 | W6: 54.841061 | X6: 2.494138 | Y6: 2 | Z6: 2 | AA6: 1
B7: Outstanding (In Cr) as of today | D7: Committed Forecast - Apr (In Cr) as per CRM | F7: Committed Forecast - Apr (In Cr) by Customer | H7: Monthly Registrations | Q7: Raghav Amara | R7: 89 | S7: 0 | T7: 0 | U7: 0 | V7: 81.142003 | W7: 81.118154 | X7: 0.0238489 | Y7: 1 | Z7: 1 | AA7: 1
Q8: Raghav Marvel | R8: 88 | S8: 0 | T8: 0.25069342 | U8: 2 | V8: 58.769618 | W8: 62.063621 | X8: 0.4972083 | Y8: 2 | Z8: 2 | AA8: 4
Q9: Total | R9: =SUM(R4:R8) -> 631 | S9: =SUM(S4:S8) -> 0 | T9: =SUM(T4:T8) -> 6.1823202 | U9: =SUM(U4:U8) -> 17 | V9: =SUM(V4:V8) -> 349.34044 | W9: =SUM(W4:W8) -> 353.42893 | X9: =SUM(X4:X8) -> 10.826593 | Y9: =SUM(Y4:Y8) -> 17 | ... AA9: =SUM(AA4:AA8) -> 20
Q12: Collection Details | V12: Weekly Forecast
Q13: Project | R13: Target | S13: Achievement | T13: Achievement % | U13: Forecast | V13: Weekly Forecast | W13: Customer Committed Amount | X13: Raghav Paradise | Y13: Raghav Parijat | Z13: Raghav Nova | AA13: Raghav Amara | AB13: Raghav Marvel | AD13: Ageing Collection Outstanding - Weekly | AE13: Raghav Paradise | AF13: Raghav Parijat | AG13: Raghav Nova | AH13: Raghav Amara | AI13: Raghav Marvel | AJ13: Total
Q14: Raghav Paradise | R14: 9.2006137 | S14: 1.4810675 | T14: =S14/R14 -> 0.16097486 | U14: 45 | V14: Week 1 | W14: =SUM(X14:AB14) -> 0.1019472 | X14: 0.0509736 | Y14: 0.0509736 | Z14: 0 | AA14: 0 | AB14: 0 | AD14: <= 30 days Outstanding | AE14: 0 | AF14: Pending Collection | AG14: 0 | AH14: 0 | AI14: 0 | AJ14: =SUM(AE14:AI14) -> 0
Q15: Raghav Parijat | R15: 9.2006137 | S15: 1.4810675 | T15: =S15/R15 -> 0.16097486 | U15: 44 | V15: Week 2 | W15: =SUM(X15:AB15) -> 0.6684044 | X15: 0.3342022 | Y15: 0.3342022 | Z15: 0 | AA15: 0 | AB15: 0 | AD15: 31 to 60 days Outstanding | AE15: 0 | AF15: 0 | AG15: 0 | AH15: 0 | AI15: 0 | AJ15: =SUM(AE15:AI15) -> 0
Q16: Raghav Nova | R16: 3.5328284 | S16: 2.3140931 | T16: =S16/R16 -> 0.65502563 | U16: 46 | V16: Week 3 | W16: =SUM(X16:AB16) -> 2.8459081 | X16: 1.0216391 | Y16: 1.0216391 | Z16: 0.8026299 | AA16: 0 | AB16: 0 | AD16: 61 to 90 days Outstanding | AE16: 0 | AF16: 0 | AG16: 0 | AH16: 0 | AI16: 0 | AJ16: =SUM(AE16:AI16) -> 0
Q17: Raghav Amara | R17: 0.0238489 | S17: 0 | T17: =S17/R17 -> 0 | U17: 44 | V17: Week 4 | W17: =SUM(X17:AB17) -> 3.0478017 | X17: 1.4966246 | Y17: 1.4966246 | Z17: 0 | AA17: 0 | AB17: 0.0545525 | AD17: 91 to 120 days Outstanding | AE17: 0 | AF17: 0 | AG17: 0 | AH17: 0 | AI17: 0 | AJ17: =SUM(AE17:AI17) -> 0
Q18: Raghav Marvel | R18: 0.3161802 | S18: 0.25069342 | T18: =S18/R18 -> 0.79288146 | U18: 45 | V18: Spill Over | W18: =SUM(X18:AB18) -> 0 | X18: 0 | Y18: 0 | Z18: 0 | AA18: 0 | AB18: 0 | AD18: 121 - 150 days Outstanding | AE18: 0 | AF18: 0 | AG18: 0 | AH18: 0 | AI18: 0 | AJ18: =SUM(AE18:AI18) -> 0
Q19: Overall | R19: =SUM(R14:R18) -> 22.274085 | S19: =SUM(S14:S18) -> 5.5269216 | T19: =S19/R19 -> 0.24813237 | V19: Total Expected | W19: =SUM(W14:W18) -> 6.6640614 | X19: =SUM(X14:X18) -> 2.9034395 | Y19: =SUM(Y14:Y17) -> 2.9034395 | Z19: =SUM(Z14:Z17) -> 0.8026299 | AA19: =SUM(AA14:AA17) -> 0 | AB19: =SUM(AB14:AB17) -> 0.0545525 | AD19: 151 - 180 days Outstanding | AE19: 0 | AF19: 0 | AG19: 0 | AH19: 0 | AI19: 0 | AJ19: =SUM(AE19:AI19) -> 0
AD20: > 180 days Outstanding | AE20: 0 | AF20: 0 | AG20: 0 | AH20: 0 | AI20: 0 | AJ20: =SUM(AE20:AI20) -> 0
AD21: Total | AE21: =SUM(AE14:AE20) -> 0 | AF21: =SUM(AF14:AF20) -> 0 | AG21: =SUM(AG14:AG20) -> 0 | AH21: =SUM(AH14:AH20) -> 0 | AI21: =SUM(AI14:AI20) -> 0 | AJ21: =SUM(AE21:AI21) -> 0
M23: Paradise
M24: Otustanding Ageing | N24: Amount Collected

Sheet Overall_Draft
B1: Overall Summary (Daily) | G1: Date: | I1: =TODAY() -> 46149
B2: CRM: Target vs Achievements | F2: Sales: Target vs Achievement | I2: Overall Collection
B3: =CONCATENATE("₹ ",ROUND($N$27,2)," / ",ROUND($M$27,2)," (",ROUND($O$27,3)*100,"%)") -> ₹ 27.53 / 44.92 (61.3%) | F3: =CONCATENATE("₹ ", ROUND($U$21,2), " / ", "₹ ", ROUND($T$21,2)) -> ₹ 1.48 / ₹ 2.21 | G3: =CONCATENATE("₹ ", ROUND($U$22,2), " / ", "₹ ", ROUND($T$22,2)) -> ₹ 0.6 / ₹ 0 | I3: =CONCATENATE("₹ ",ROUND($N$11,2), " | ", "₹ ",ROUND($O$11,2)) -> ₹ 0 | ₹ 29.7 | L3: Projects | M3: Total Live Bookings | N3: Daily Collection (In Cr) | O3: Monthly Collection (In Cr) | P3: Monthly Registrations | Q3: Actual Demand Raised (In Cr) till date | R3: Collection (In Cr) till date | S3: Outstanding (In Cr) till date | T3: Pending Registrations | U3: Pending Registrations (> 45 days) | V3: Registration Targets | W3: Outstanding (In Cr) till date
B4: CRM Monthly Target vs Achievement (In Cr) | F4: OCR till 10% (In Cr.) | G4: Monthly New Bookings (In Cr.) | I4: Daily | Monthly Collection (In Cr) (Includes Sales + CRM) | L4: RAGHAV Paradise | M4: ='[1]Project Summary'!$B$7 -> 187 | N4: ='[1]Project Summary'!$D$7 -> 0 | O4: ='[1]Project Summary'!$E$7 -> 4.4807139 | P4: ='[1]Project Summary'!$F$7 -> 1 | Q4: ='[1]Project Summary'!$C$14 -> 206.69615 | R4: ='[1]Project Summary'!$D$14 -> 205.64925 | S4: ='[1]Project Summary'!$E$14 -> 3.6806382 | T4: ='[1]Project Summary'!$D$21 -> 1 | U4: ='[1]Project Summary'!$F$21 -> 1 | V4: ='[1]Project Summary'!$Q$3 -> 0 | X4: ='[1]Project Summary'!$R$3 -> 0
F5: Registrations (Sales) | L5: RAGHAV Parijat | M5: ='[2]Project Summary'!$B$7 -> 105 | N5: ='[2]Project Summary'!$D$7 -> 0 | O5: ='[2]Project Summary'!$E$7 -> 8.650219 | P5: ='[2]Project Summary'!$F$7 -> 0 | Q5: ='[2]Project Summary'!$C$13 -> 101.85286 | R5: ='[2]Project Summary'!$D$13 -> 96.866328 | S5: ='[2]Project Summary'!$E$13 -> 5.9417039 | T5: ='[2]Project Summary'!$D$20 -> 1 | U5: ='[2]Project Summary'!$F$20 -> 1 | V5: ='[2]Project Summary'!$Q$3 -> 1 | X5: ='[2]Project Summary'!$R$3 -> 0
B6: =P27 -> 22.59 | D6: =$S$11-AC54-AC55 -> 15.322573 | F6: =CONCATENATE($U$11, " | ", $T$11) -> 30 | 47 | G6: =CONCATENATE($P$11," / ",V11) -> 18 / 25 | I6: =$S$11 -> 16.891745 | L6: RAGHAV ANANTA | M6: ='[3]Project Summary'!$B$7 -> 74 | N6: ='[3]Project Summary'!$D$7 -> 0 | O6: ='[3]Project Summary'!$E$7 -> 5.3060298 | P6: ='[3]Project Summary'!$F$7 -> 4 | Q6: ='[3]Project Summary'!$C$13 -> 45.568175 | R6: ='[3]Project Summary'!$D$13 -> 46.860069 | S6: ='[3]Project Summary'!$E$13 -> 1.615276 | T6: ='[3]Project Summary'!$D$20 -> 15 | U6: ='[3]Project Summary'!$F$20 -> 10 | V6: ='[3]Project Summary'!$Q$3 -> 10 | X6: ='[3]Project Summary'!$R$3 -> 8
B7: CRM Monthly Forecast (In Cr.) | D7: CRM Outstanding (In Cr) as of today | F7: Pending Registrations | G7: Monthly Registrations Targets | I7: Outstanding (In Cr) as of today | L7: RAGHAV Vista | M7: ='[4]Project Summary'!$B$7 -> 50 | N7: ='[4]Project Summary'!$D$7 -> 0 | O7: ='[4]Project Summary'!$E$7 -> 3.9736441 | P7: ='[4]Project Summary'!$F$7 -> 4 | Q7: ='[4]Project Summary'!$C$13 -> 33.941633 | R7: ='[4]Project Summary'!$D$13 -> 33.694863 | S7: ='[4]Project Summary'!$E$13 -> 0.5885487 | T7: ='[4]Project Summary'!$D$20 -> 3 | U7: ='[4]Project Summary'!$F$20 -> 1 | V7: ='[4]Project Summary'!$Q$3 -> 7 | X7: ='[4]Project Summary'!$R$3 -> 6
L8: RAGHAV Avenue | M8: ='[5]Project Summary'!$B$7 -> 54 | N8: ='[5]Project Summary'!$D$7 -> 0 | O8: ='[5]Project Summary'!$E$7 -> 4.2654046 | P8: ='[5]Project Summary'!$F$7 -> 7 | Q8: ='[5]Project Summary'!$C$13 -> 23.986368 | R8: ='[5]Project Summary'!$D$13 -> 24.688711 | S8: ='[5]Project Summary'!$E$13 -> 2.6275068 | T8: ='[5]Project Summary'!$D$20 -> 11 | U8: ='[5]Project Summary'!$F$20 -> 8 | V8: ='[5]Project Summary'!$Q$3 -> 6 | X8: ='[5]Project Summary'!$R$3 -> 6
L9: RAGHAV UTOPIA | M9: ='[6]Project Summary'!$B$7 -> 16 | N9: ='[6]Project Summary'!$D$7 -> 0 | O9: ='[6]Project Summary'!$E$7 -> 0.82010581 | P9: ='[6]Project Summary'!$F$7 -> 2 | Q9: ='[6]Project Summary'!$C$13 -> 1.3584535 | R9: ='[6]Project Summary'!$D$13 -> 1.4807048 | S9: ='[6]Project Summary'!$E$13 -> 0.4765766 | T9: ='[6]Project Summary'!$D$20 -> 13 | U9: ='[6]Project Summary'!$F$20 -> 6 | V9: ='[6]Project Summary'!$Q$3 -> 0 | X9: ='[6]Project Summary'!$R$3 -> 0
L10: RAGHAV Enclave | M10: ='[7]Project Summary'!$B$7 -> 24 | N10: ='[7]Project Summary'!$D$7 -> 0 | O10: ='[7]Project Summary'!$E$7 -> 2.205519 | P10: ='[7]Project Summary'!$F$7 -> 0 | Q10: ='[7]Project Summary'!$C$13 -> 19.816488 | R10: ='[7]Project Summary'!$D$13 -> 18.298131 | S10: ='[7]Project Summary'!$E$13 -> 1.961495 | T10: ='[7]Project Summary'!$D$20 -> 3 | U10: ='[7]Project Summary'!$F$20 -> 3 | V10: ='[7]Project Summary'!$Q$3 -> 1 | X10: ='[7]Project Summary'!$R$3 -> 1
L11: Total | M11: =SUM(M4:M10) -> 510 | N11: =SUM(N4:N10) -> 0 | O11: =SUM(O4:O10) -> 29.701636 | P11: =SUM(P4:P10) -> 18 | Q11: =SUM(Q4:Q10) -> 433.22012 | R11: =SUM(R4:R10) -> 427.53806 | S11: =SUM(S4:S10) -> 16.891745 | T11: =SUM(T4:T10) -> 47 | ... X11: =SUM(X4:X10) -> 21
L18: Project wise: Target vs Achievement Status | S18: Category wise: Target vs Achievement Status
L19: Project | M19: Target | N19: Achievement | O19: Achievement % | P19: Forecast as per CRM | Q19: Forecast - Achievement | S19: TARGET CATEGORY | T19: Target | U19: Achievement | V19: Achievement % | W19: Forecast as per CRM | X19: Balance
L20: RAGHAV Paradise | M20: ='[1]Project Summary'!$I$13-Q36 -> 6.0278847 | N20: ='[1]Project Summary'!$J$13-R36 -> 4.4100472 | O20: =N20/M20 -> 0.73160776 | P20: ='[1]Project Summary'!$L$13-T36 -> 2.04 | Q20: =P20-N20 -> -2.3700472 | S20: Spill Over | T20: =M43 -> 13.397007 | U20: =N43 -> 7.0392804 | V20: =O43 -> 0.52543679 | W20: =P43 -> 7.24 | X20: =T20-W20 -> 6.1570072
L21: RAGHAV Parijat | M21: ='[2]Project Summary'!$I$13-Q37 -> 14.267345 | N21: ='[2]Project Summary'!$J$13-R37 -> 8.650219 | O21: =N21/M21 -> 0.60629492 | P21: ='[2]Project Summary'!$L$13-T37 -> 0.68 | Q21: =P21-N21 -> -7.970219 | S21: OCR - Unregistered Bookings | T21: =Q43 -> 2.2067938 | U21: =R43 -> 1.4775612 | V21: =S43 -> 0.66955111 | W21: =T43 -> 0.2 | X21: =T21-W21 -> 2.0067938
L22: RAGHAV ANANTA | M22: ='[3]Project Summary'!$I$13-Q38 -> 8.0769664 | N22: ='[3]Project Summary'!$J$13-R38 -> 4.5209203 | O22: =N22/M22 -> 0.55972999 | P22: ='[3]Project Summary'!$L$13-T38 -> 6.35 | Q22: =P22-N22 -> 1.8290797 | S22: OCR - New Bookings | T22: =U43 -> 0 | U22: =V43 -> 0.6036921 | V22: =W43 -> #DIV/0! | W22: =X43 -> 0 | X22: =T22-W22 -> 0
L23: RAGHAV Vista | M23: ='[4]Project Summary'!$I$13-Q39 -> 7.2772421 | N23: ='[4]Project Summary'!$J$13-R39 -> 3.8847442 | O23: =N23/M23 -> 0.53382094 | P23: ='[4]Project Summary'!$L$13-T39 -> 5.05 | Q23: =P23-N23 -> 1.1652558 | S23: =CONCATENATE("Demand For Registrations post 20th of last month") -> Demand For Registrations post 20th of last month | T23: =Y43 -> 5.4110873 | U23: =Z43 -> 5.5059146 | V23: =AA43 -> 1.0175246 | W23: =AB43 -> 5.41 | X23: =T23-W23 -> 0.0010873
L24: RAGHAV Avenue | M24: ='[5]Project Summary'!$I$13-Q40 -> 4.9720375 | N24: ='[5]Project Summary'!$J$13-R40 -> 4.0402514 | O24: =N24/M24 -> 0.81259472 | P24: ='[5]Project Summary'!$L$13-T40 -> 4.17 | Q24: =P24-N24 -> 0.12974859 | S24: =CONCATENATE("Expected New Monthly Registrations") -> Expected New Monthly Registrations | T24: =AC43 -> 13.69 | U24: =AD43 -> 6.7300527 | V24: =AE43 -> 0.49160356 | W24: =AF43 -> 9.37 | X24: =T24-W24 -> 4.32
L25: RAGHAV UTOPIA | M25: ='[6]Project Summary'!$I$13-Q41 -> 0 | N25: ='[6]Project Summary'!$J$13-R41 -> 0 | O25: =N25/M25 -> #DIV/0! | P25: ='[6]Project Summary'!$L$13-T41 -> 0 | Q25: =P25-N25 -> 0 | S25: New Slab / New Demand | T25: =AG43 -> 12.42 | U25: =AH43 -> 8.2525539 | V25: =AI43 -> 0.66445684 | W25: =AJ43 -> 0.57 | X25: =T25-W25 -> 11.85
L26: RAGHAV Enclave | M26: ='[7]Project Summary'!$I$13-Q42 -> 4.2966186 | N26: ='[7]Project Summary'!$J$13-R42 -> 2.0216195 | O26: ='[7]Project Summary'!$K$13 -> 0.49157712 | P26: ='[7]Project Summary'!$L$13-T42 -> 4.3 | Q26: =P26-N26 -> 2.2783805
L27: Overall | M27: =SUM(M20:M26) -> 44.918095 | N27: =SUM(N20:N26) -> 27.527802 | O27: =N27/M27 -> 0.61284438 | P27: =SUM(P20:P26) -> 22.59 | Q27: =P27-N27 -> -4.9378017
M34: Spill Over from Registered Bookings | Q34: OCR - Unregistered Bookings | U34: =CONCATENATE("OCR - Expected New Bookings in"," Sept") -> OCR - Expected New Bookings in Sept | Y34: =CONCATENATE("Demand Raised for Registrations after ","20th of last month") -> Demand Raised for Registrations after 20th of last month | AC34: =CONCATENATE("Expected Registrations in August ",$D$3,"'",$I$3," ") -> Expected Registrations in August '₹ 0 | ₹ 29.7 | AG34: Slab Amount / Possession Amt
L35: Target Headers | M35: Collection Target | N35: Collection Achievement | O35: Achievement % | P35: Forecast as per CRM | Q35: Collection Target | R35: Collection Achievement | S35: Achievement % | T35: Forecast as per CRM | U35: Collection Target | V35: Collection Achievement | W35: Achievement % | X35: Forecast as per CRM | Y35: Collection Target | Z35: Collection Achievement | AA35: Achievement % | AB35: Forecast as per CRM | AC35: Collection Target | AD35: Collection Achievement | AE35: Achievement % | AF35: Forecast as per CRM | AG35: Collection Target | AH35: Collection Achievement | AI35: Achievement % | AJ35: Forecast as per CRM
L36: Paradise | M36: ='[1]Project Summary'!$I$7 -> 6.0278847 | N36: ='[1]Project Summary'!$J$7 -> 2.5798586 | O36: =N36/M36 -> 0.42798738 | P36: ='[1]Project Summary'!$L$7 -> 2.04 | Q36: ='[1]Project Summary'!$I$8 -> 0.2030189 | R36: ='[1]Project Summary'!$J$8 -> 0 | S36: =R36/Q36 -> 0 | T36: ='[1]Project Summary'!$L$8 -> 0.2 | U36: ='[1]Project Summary'!$I$9 -> 0 | V36: ='[1]Project Summary'!$J$9 -> 0 | W36: =V36/U36 -> #DIV/0! | X36: ='[1]Project Summary'!$L$9 -> 0 | Y36: ='[1]Project Summary'!$I$10 -> 0 | Z36: ='[1]Project Summary'!$J$10 -> 0 | AA36: =Z36/Y36 -> #DIV/0! | AB36: ='[1]Project Summary'!$L$10 -> 0 | AC36: ='[1]Project Summary'!$I$11 -> 0 | AD36: ='[1]Project Summary'!$J$11 -> 1.8301886 | AE36: =AD36/AC36 -> #DIV/0! | AF36: ='[1]Project Summary'!$L$11 -> 0 | AG36: ='[1]Project Summary'!$I$12 -> 0 | AH36: ='[1]Project Summary'!$J$12 -> 0 | AI36: =AH36/AG36 -> #DIV/0! | AJ36: ='[1]Project Summary'!$L$12 -> 0
L37: Raghav Parijat | M37: ='[2]Project Summary'!$I$7 -> 2.4173452 | N37: ='[2]Project Summary'!$J$7 -> 1.1720278 | O37: =N37/M37 -> 0.48484091 | P37: ='[2]Project Summary'!$L$7 -> 0.68 | Q37: ='[2]Project Summary'!$I$8 -> 0 | R37: ='[2]Project Summary'!$J$8 -> 0 | S37: =R37/Q37 -> #DIV/0! | T37: ='[2]Project Summary'!$L$8 -> 0 | U37: ='[2]Project Summary'!$I$9 -> 0 | V37: ='[2]Project Summary'!$J$9 -> 0 | W37: =V37/U37 -> #DIV/0! | X37: ='[2]Project Summary'!$L$9 -> 0 | Y37: ='[2]Project Summary'!$I$10 -> 0 | Z37: ='[2]Project Summary'!$J$10 -> 0 | AA37: =Z37/Y37 -> #DIV/0! | AB37: ='[2]Project Summary'!$L$10 -> 0 | AC37: ='[2]Project Summary'!$I$11 -> 0 | AD37: ='[2]Project Summary'!$J$11 -> 0 | AE37: =AD37/AC37 -> #DIV/0! | AF37: ='[2]Project Summary'!$L$11 -> 0 | AG37: ='[2]Project Summary'!$I$12 -> 11.85 | AH37: ='[2]Project Summary'!$J$12 -> 7.4781911 | AI37: =AH37/AG37 -> 0.63107098 | AJ37: ='[2]Project Summary'!$L$12 -> 0 | AK37: =AJ37/AG37 -> 0
L38: RAGHAV ANANTA | M38: ='[3]Project Summary'!$I$7 -> 2.2269664 | N38: ='[3]Project Summary'!$J$7 -> 1.6921175 | O38: =N38/M38 -> 0.75983072 | P38: ='[3]Project Summary'!$L$7 -> 2.08 | Q38: ='[3]Project Summary'!$I$8 -> 0.4893001 | R38: ='[3]Project Summary'!$J$8 -> 0.51428571 | S38: =R38/Q38 -> 1.051064 | T38: ='[3]Project Summary'!$L$8 -> 0 | U38: ='[3]Project Summary'!$I$9 -> 0 | V38: ='[3]Project Summary'!$J$9 -> 0.31844276 | W38: =V38/U38 -> #DIV/0! | X38: ='[3]Project Summary'!$L$9 -> 0 | Y38: ='[3]Project Summary'!$I$10 -> 0.39 | Z38: ='[3]Project Summary'!$J$10 -> 0.30558525 | AA38: =Z38/Y38 -> 0.78355192 | AB38: ='[3]Project Summary'!$L$10 -> 0.39 | AC38: ='[3]Project Summary'!$I$11 -> 5.46 | AD38: ='[3]Project Summary'!$J$11 -> 1.9107596 | AE38: =AD38/AC38 -> 0.34995598 | AF38: ='[3]Project Summary'!$L$11 -> 3.88 | AG38: ='[3]Project Summary'!$I$12 -> 0 | AH38: ='[3]Project Summary'!$J$12 -> 0.612458 | AI38: =AH38/AG38 -> #DIV/0! | AJ38: ='[3]Project Summary'!$L$12 -> 0
L39: Raghav Vista | M39: ='[4]Project Summary'!$I$7 -> 0.4572421 | N39: ='[4]Project Summary'!$J$7 -> 0.33286333 | O39: =N39/M39 -> 0.7279805 | P39: ='[4]Project Summary'!$L$7 -> 0.46 | Q39: ='[4]Project Summary'!$I$8 -> 0.4936549 | R39: ='[4]Project Summary'!$J$8 -> 0.035090286 | S39: =R39/Q39 -> 0.071082624 | T39: ='[4]Project Summary'!$L$8 -> 0 | U39: ='[4]Project Summary'!$I$9 -> 0 | V39: ='[4]Project Summary'!$J$9 -> 0.0094285714 | W39: =V39/U39 -> #DIV/0! | X39: ='[4]Project Summary'!$L$9 -> 0 | Y39: ='[4]Project Summary'!$I$10 -> 2.43 | Z39: ='[4]Project Summary'!$J$10 -> 2.8829241 | AA39: =Z39/Y39 -> 1.1863885 | AB39: ='[4]Project Summary'!$L$10 -> 2.43 | AC39: ='[4]Project Summary'!$I$11 -> 4.11 | AD39: ='[4]Project Summary'!$J$11 -> 0.507052 | AE39: =AD39/AC39 -> 0.12337032 | AF39: ='[4]Project Summary'!$L$11 -> 1.88 | AG39: ='[4]Project Summary'!$I$12 -> 0.28 | AH39: ='[4]Project Summary'!$J$12 -> 0.16190476 | AI39: =AH39/AG39 -> 0.57823129 | AJ39: ='[4]Project Summary'!$L$12 -> 0.28
L40: RAGHAV Avenue | M40: ='[5]Project Summary'!$I$7 -> 0.4509504 | N40: ='[5]Project Summary'!$J$7 -> 0.7862227 | O40: =N40/M40 -> 1.7434793 | P40: ='[5]Project Summary'!$L$7 -> 0.16 | Q40: ='[5]Project Summary'!$I$8 -> 0.5620902 | R40: ='[5]Project Summary'!$J$8 -> 0.16809524 | S40: =R40/Q40 -> 0.29905385 | T40: ='[5]Project Summary'!$L$8 -> 0 | U40: ='[5]Project Summary'!$I$9 -> 0 | V40: ='[5]Project Summary'!$J$9 -> 0.039048286 | W40: =V40/U40 -> #DIV/0! | X40: ='[5]Project Summary'!$L$9 -> 0 | Y40: ='[5]Project Summary'!$I$10 -> 1.4410871 | Z40: ='[5]Project Summary'!$J$10 -> 0.77197622 | AA40: =Z40/Y40 -> 0.53569019 | AB40: ='[5]Project Summary'!$L$10 -> 1.44 | AC40: ='[5]Project Summary'!$I$11 -> 2.79 | AD40: ='[5]Project Summary'!$J$11 -> 2.4820525 | AE40: =AD40/AC40 -> 0.88962455 | AF40: ='[5]Project Summary'!$L$11 -> 2.28 | AG40: ='[5]Project Summary'!$I$12 -> 0.29 | AH40: ='[5]Project Summary'!$J$12 -> 0 | AI40: =AH40/AG40 -> 0 | AJ40: ='[5]Project Summary'!$L$12 -> 0.29
L41: Raghav UTOPIA | M41: ='[6]Project Summary'!$I$7 -> 0 | N41: ='[6]Project Summary'!$J$7 -> 0 | O41: =N41/M41 -> #DIV/0! | P41: ='[6]Project Summary'!$L$7 -> 0 | Q41: ='[6]Project Summary'!$I$8 -> 0.2687297 | R41: ='[6]Project Summary'!$J$8 -> 0.57619048 | S41: =R41/Q41 -> 2.1441265 | T41: ='[6]Project Summary'!$L$8 -> 0 | U41: ='[6]Project Summary'!$I$9 -> 0 | V41: ='[6]Project Summary'!$J$9 -> 0.23677248 | W41: =V41/U41 -> #DIV/0! | X41: ='[6]Project Summary'!$L$9 -> 0 | Y41: ='[6]Project Summary'!$I$10 -> 0 | Z41: ='[6]Project Summary'!$J$10 -> 0 | AA41: =Z41/Y41 -> #DIV/0! | AB41: ='[6]Project Summary'!$L$10 -> 0 | AC41: ='[6]Project Summary'!$I$11 -> 0 | AD41: ='[6]Project Summary'!$J$11 -> 0 | AE41: =AD41/AC41 -> #DIV/0! | AF41: ='[6]Project Summary'!$L$11 -> 0 | AG41: ='[6]Project Summary'!$I$12 -> 0 | AH41: ='[6]Project Summary'!$J$12 -> 0 | AI41: =AH41/AG41 -> #DIV/0! | AJ41: ='[6]Project Summary'!$L$12 -> 0
L42: Raghav Enclave | M42: ='[7]Project Summary'!$I$7 -> 1.8166184 | N42: ='[7]Project Summary'!$J$7 -> 0.47619048 | O42: =N42/M42 -> 0.26213016 | P42: ='[7]Project Summary'!$L$7 -> 1.82 | Q42: ='[7]Project Summary'!$I$8 -> 0.19 | R42: ='[7]Project Summary'!$J$8 -> 0.18389952 | S42: =R42/Q42 -> 0.96789223 | T42: ='[7]Project Summary'!$L$8 -> 0 | U42: ='[7]Project Summary'!$I$9 -> 0 | V42: ='[7]Project Summary'!$J$9 -> 0 | W42: =V42/U42 -> #DIV/0! | X42: ='[7]Project Summary'!$L$9 -> 0 | Y42: ='[7]Project Summary'!$I$10 -> 1.1500002 | Z42: ='[7]Project Summary'!$J$10 -> 1.545429 | AA42: =Z42/Y42 -> 1.3438511 | AB42: ='[7]Project Summary'!$L$10 -> 1.15 | AC42: ='[7]Project Summary'!$I$11 -> 1.33 | AD42: ='[7]Project Summary'!$J$11 -> 0 | AE42: =AD42/AC42 -> 0 | AF42: ='[7]Project Summary'!$L$11 -> 1.33 | AG42: ='[7]Project Summary'!$I$12 -> 0 | AH42: ='[7]Project Summary'!$J$12 -> 0 | AI42: =AH42/AG42 -> #DIV/0! | AJ42: ='[7]Project Summary'!$L$12 -> 0
L43: Overall | M43: =SUM(M36:M42) -> 13.397007 | N43: =SUM(N36:N42) -> 7.0392804 | O43: =N43/M43 -> 0.52543679 | P43: =SUM(P36:P42) -> 7.24 | Q43: =SUM(Q36:Q42) -> 2.2067938 | R43: =SUM(R36:R42) -> 1.4775612 | S43: =R43/Q43 -> 0.66955111 | T43: =SUM(T36:T42) -> 0.2 | U43: =SUM(U36:U42) -> 0 | V43: =SUM(V36:V42) -> 0.6036921 | W43: =V43/U43 -> #DIV/0! | X43: =SUM(X36:X42) -> 0 | Y43: =SUM(Y36:Y42) -> 5.4110873 | Z43: =SUM(Z36:Z42) -> 5.5059146 | AA43: =Z43/Y43 -> 1.0175246 | AB43: =SUM(AB36:AB42) -> 5.41 | AC43: =SUM(AC36:AC42) -> 13.69 | AD43: =SUM(AD36:AD42) -> 6.7300527 | AE43: =AD43/AC43 -> 0.49160356 | AF43: =SUM(AF36:AF42) -> 9.37 | AG43: =SUM(AG36:AG42) -> 12.42 | AH43: =SUM(AH36:AH42) -> 8.2525539 | AI43: =AH43/AG43 -> 0.66445684 | AJ43: =SUM(AJ36:AJ42) -> 0.57
Q45: =M27-Q43 -> 42.711301 | R45: =N27-R43 -> 26.05024
U51: Outstanding
L52: Weekly Forecast | U52: Headers | V52: Raghav Paradise | W52: Raghav Parijat | X52: RAGHAV ANANTA | Y52: Raghav Vista | Z52: RAGHAV Avenue | AA52: Raghav UTOPIA | AB52: Raghav Enclave | AC52: Total
L53: Weekly Forecast | M53: Customer Committed Amount | N53: RAGHAV Paradise | O53: RAGHAV Parijat | P53: RAGHAV ANANTA | Q53: RAGHAV Vista | R53: RAGHAV UTOPIA | S53: RAGHAV Enclave | U53: Spill Over | V53: ='[1]Project Summary'!$L$18 -> 3.6806382 | W53: ='[2]Project Summary'!$L$18 -> 5.9034896 | X53: ='[3]Project Summary'!$L$18 -> 0.48546493 | Y53: ='[4]Project Summary'!$L$18 -> 0.24255796 | Z53: ='[5]Project Summary'!$L$18 -> 0.2919116 | AA53: ='[6]Project Summary'!$L$18 -> 0 | AB53: ='[7]Project Summary'!$L$18 -> 1.5309041 | AC53: =SUM(V53:AB53) -> 12.134966
L54: Week 1 | M54: =SUM(N54:R54) -> 1.1717345 | N54: ='[1]Project Summary'!$I$18 -> 1.1717345 | R54: ='[6]Project Summary'!$I$18 -> 0 | U54: Own Contribution (OCR) - Unregistered | V54: ='[1]Project Summary'!$L$19 -> 0 | W54: ='[2]Project Summary'!$L$19 -> 0.0382143 | X54: ='[3]Project Summary'!$L$19 -> 1e-07 | Y54: ='[4]Project Summary'!$L$19 -> 0.0885713 | Z54: ='[5]Project Summary'!$L$19 -> 0.421614 | AA54: ='[6]Project Summary'!$L$19 -> 0.4765766 | AB54: ='[7]Project Summary'!$L$19 -> 0.41800528 | AC54: =SUM(V54:AB54) -> 1.4429816
L55: Week 2 | M55: =SUM(N55:R55) -> 2.3479263 | N55: ='[1]Project Summary'!$I$19 -> 2.2479263 | R55: ='[6]Project Summary'!$I$19 -> 0.1 | U55: OCR - New Bookings | V55: ='[1]Project Summary'!$L$20 -> 0 | W55: ='[2]Project Summary'!$L$20 -> 0 | X55: ='[3]Project Summary'!$L$20 -> 0 | Y55: ='[4]Project Summary'!$L$20 -> 0 | Z55: ='[5]Project Summary'!$L$20 -> 0.12619049 | AA55: ='[6]Project Summary'!$L$20 -> 0 | AB55: ='[7]Project Summary'!$L$20 -> 0 | AC55: =SUM(V55:AB55) -> 0.12619049
L56: Week 3 | M56: =SUM(N56:R56) -> 0.7007274 | N56: ='[1]Project Summary'!$I$20 -> 0.7007274 | R56: ='[6]Project Summary'!$I$20 -> 0 | U56: =CONCATENATE("Demand For Registrations post 20th of last month") -> Demand For Registrations post 20th of last month | V56: ='[1]Project Summary'!$L$2 -> 0 | W56: ='[2]Project Summary'!$L$21 -> 0 | X56: ='[3]Project Summary'!$L$21 -> 0.19047625 | Y56: ='[4]Project Summary'!$L$21 -> 0.20846761 | Z56: ='[5]Project Summary'!$L$21 -> 1.7596301 | AA56: ='[6]Project Summary'!$L$21 -> 0 | AB56: ='[7]Project Summary'!$L$21 -> 0.01258561 | AC56: =SUM(V56:AB56) -> 2.1711596
L57: Week 4 | M57: =SUM(N57:R57) -> 1.4966375 | N57: ='[1]Project Summary'!$I$21 -> 1.4966375 | R57: ='[6]Project Summary'!$I$21 -> 0 | U57: =CONCATENATE("Expected New Monthly Registrations") -> Expected New Monthly Registrations | V57: ='[1]Project Summary'!$L$22 -> 0 | W57: ='[2]Project Summary'!$L$22 -> 0 | X57: ='[3]Project Summary'!$L$22 -> 0.93933469 | Y57: ='[4]Project Summary'!$L$22 -> 0.048951824 | Z57: ='[5]Project Summary'!$L$22 -> 0.028160576 | AA57: ='[6]Project Summary'!$L$22 -> 0 | AB57: ='[7]Project Summary'!$L$22 -> 0 | AC57: =SUM(V57:AB57) -> 1.0164471
L58: Week 5 | M58: =SUM(N58:R58) -> 0.0489544 | N58: ='[1]Project Summary'!$I$22 -> 0.0489544 | R58: ='[6]Project Summary'!$I$22 -> 0 | U58: Total | V58: =SUM(V53:V57) -> 3.6806382 | W58: =SUM(W53:W57) -> 5.9417039 | X58: =SUM(X53:X57) -> 1.615276 | Y58: =SUM(Y53:Y57) -> 0.5885487 | Z58: =SUM(Z53:Z57) -> 2.6275068 | AA58: =SUM(AA53:AA57) -> 0.4765766 | AB58: =SUM(AB53:AB57) -> 1.961495 | AC58: =SUM(AC53:AC57) -> 16.891745
...

Sheet Reporting
B1: Project | C1: Target | D1: Achievement | E1: Achievement % | F1: Forecast as per CRM | G1: Forecast - Achievement | H1: =Overall_Draft!L3 -> Projects | I1: =Overall_Draft!M3 -> Total Live Bookings | J1: =Overall_Draft!N3 -> Daily Collection (In Cr) | K1: =Overall_Draft!O3 -> Monthly Collection (In Cr) | L1: =Overall_Draft!P3 -> Monthly Registrations | M1: =Overall_Draft!Q3 -> Actual Demand Raised (In Cr) till date | N1: =Overall_Draft!R3 -> Collection (In Cr) till date | O1: =Overall_Draft!S3 -> Outstanding (In Cr) till date | ... S1: =Overall_Draft!W3 -> Outstanding (In Cr) till date | T1: b | U1: Target Headers | V1: Spill Over Collection Target | W1: Spill Over Collection Achievement | X1: Spill Over Achievement % | Y1: Spill Over Forecast as per CRM | Z1: OCR Collection Target | AA1: OCR Collection Achievement | AB1: OCR Achievement % | AC1: OCR Forecast as per CRM | AD1: New Booking Collection Target | AE1: New Booking Collection Achievement | AF1: New Booking Achievement % | AG1: New Booking Forecast as per CRM | AH1: Demands for Registration post 20th Collection Target | AI1: Demands for Registration post 20th Collection Achievement | AJ1: Demands for Registration post 20th Achievement % | AK1: Demands for Registration post 20th Forecast as per CRM | AL1: Expected Registrations Collection Target | AM1: Expected Registrations Collection Achievement | AN1: Expected Registrations Achievement % | AO1: Expected Registrations Forecast as per CRM | AP1: Slab Amount Collection Target | AQ1: Slab Amount Collection Achievement | AR1: Slab Amount Achievement % | AS1: Slab Amount Forecast as per CRM | AV1: =Overall!S19 -> TARGET CATEGORY | AW1: =Overall!T19 -> Target | AX1: =Overall!U19 -> Achievement | AY1: =Overall!V19 -> Achievement % | AZ1: =Overall!W19 -> Forecast as per CRM | BA1: =Overall!X19 -> Balance
B2: =Overall_Draft!L20 -> RAGHAV Paradise | C2: =Overall_Draft!M20 -> 6.0278847 | D2: =Overall_Draft!N20 -> 4.4100472 | E2: =IFERROR(D2/C2,"") -> 0.73160776 | F2: =Overall_Draft!P20 -> 2.04 | G2: =Overall_Draft!Q20 -> -2.3700472 | H2: =Overall_Draft!L4 -> RAGHAV Paradise | I2: =Overall_Draft!M4 -> 187 | J2: =Overall_Draft!N4 -> 0 | K2: =Overall_Draft!O4 -> 4.4807139 | L2: =Overall_Draft!P4 -> 1 | M2: =Overall_Draft!Q4 -> 206.69615 | N2: =Overall_Draft!R4 -> 205.64925 | O2: =Overall_Draft!S4 -> 3.6806382 | ... S2: =Overall_Draft!W4 -> 0 | U2: =Overall_Draft!L36 -> Paradise | V2: =Overall_Draft!M36 -> 6.0278847 | W2: =Overall_Draft!N36 -> 2.5798586 | X2: =Overall_Draft!O36 -> 0.42798738 | Y2: =Overall_Draft!P36 -> 2.04 | Z2: =Overall_Draft!Q36 -> 0.2030189 | AA2: =Overall_Draft!R36 -> 0 | AB2: =Overall_Draft!S36 -> 0 | ... AS2: =Overall_Draft!AJ36 -> 0 | AV2: =Overall!S20 -> Spill Over | AW2: =Overall!T20 -> 13.627007 | AX2: =Overall!U20 -> 7.0392804 | AY2: =Overall!V20 -> 0.51656834 | AZ2: =Overall!W20 -> 7.24 | BA2: =Overall!X20 -> 6.3870072
B3: =Overall_Draft!L21 -> RAGHAV Parijat | C3: =Overall_Draft!M21 -> 14.267345 | D3: =Overall_Draft!N21 -> 8.650219 | E3: =IFERROR(D3/C3,"") -> 0.60629492 | F3: =Overall_Draft!P21 -> 0.68 | G3: =Overall_Draft!Q21 -> -7.970219 | H3: =Overall_Draft!L5 -> RAGHAV Parijat | I3: =Overall_Draft!M5 -> 105 | J3: =Overall_Draft!N5 -> 0 | K3: =Overall_Draft!O5 -> 8.650219 | L3: =Overall_Draft!P5 -> 0 | M3: =Overall_Draft!Q5 -> 101.85286 | N3: =Overall_Draft!R5 -> 96.866328 | O3: =Overall_Draft!S5 -> 5.9417039 | ... S3: =Overall_Draft!W5 -> 0 | U3: =Overall_Draft!L37 -> Raghav Parijat | V3: =Overall_Draft!M37 -> 2.4173452 | W3: =Overall_Draft!N37 -> 1.1720278 | X3: =Overall_Draft!O37 -> 0.48484091 | Y3: =Overall_Draft!P37 -> 0.68 | Z3: =Overall_Draft!Q37 -> 0 | AA3: =Overall_Draft!R37 -> 0 | AB3: =Overall_Draft!S37 -> #DIV/0! | ... AS3: =Overall_Draft!AJ37 -> 0 | AV3: =Overall!S21 -> Own Contribution (OCR) - Unregistered | AW3: =Overall!T21 -> 1.9380641 | AX3: =Overall!U21 -> 0.90137076 | AY3: =Overall!V21 -> 0.46508821 | AZ3: =Overall!W21 -> 0.2 | BA3: =Overall!X21 -> 1.7380641
B4: =Overall_Draft!L22 -> RAGHAV ANANTA | C4: =Overall_Draft!M22 -> 8.0769664 | D4: =Overall_Draft!N22 -> 4.5209203 | E4: =IFERROR(D4/C4,"") -> 0.55972999 | F4: =Overall_Draft!P22 -> 6.35 | G4: =Overall_Draft!Q22 -> 1.8290797 | H4: =Overall_Draft!L6 -> RAGHAV ANANTA | I4: =Overall_Draft!M6 -> 74 | J4: =Overall_Draft!N6 -> 0 | K4: =Overall_Draft!O6 -> 5.3060298 | L4: =Overall_Draft!P6 -> 4 | M4: =Overall_Draft!Q6 -> 45.568175 | N4: =Overall_Draft!R6 -> 46.860069 | O4: =Overall_Draft!S6 -> 1.615276 | ... S4: =Overall_Draft!W6 -> 0 | U4: =Overall_Draft!L38 -> RAGHAV ANANTA | V4: =Overall_Draft!M38 -> 2.2269664 | W4: =Overall_Draft!N38 -> 1.6921175 | X4: =Overall_Draft!O38 -> 0.75983072 | Y4: =Overall_Draft!P38 -> 2.08 | Z4: =Overall_Draft!Q38 -> 0.4893001 | AA4: =Overall_Draft!R38 -> 0.51428571 | AB4: =Overall_Draft!S38 -> 1.051064 | ... AS4: =Overall_Draft!AJ38 -> 0 | AV4: =Overall!S22 -> OCR - New Bookings | AW4: =Overall!T22 -> 0 | AX4: =Overall!U22 -> 0.36691962 | AY4: =Overall!V22 -> #DIV/0! | AZ4: =Overall!W22 -> 0 | BA4: =Overall!X22 -> 0
B5: =Overall_Draft!L23 -> RAGHAV Vista | C5: =Overall_Draft!M23 -> 7.2772421 | D5: =Overall_Draft!N23 -> 3.8847442 | E5: =IFERROR(D5/C5,"") -> 0.53382094 | F5: =Overall_Draft!P23 -> 5.05 | G5: =Overall_Draft!Q23 -> 1.1652558 | H5: =Overall_Draft!L7 -> RAGHAV Vista | I5: =Overall_Draft!M7 -> 50 | J5: =Overall_Draft!N7 -> 0 | K5: =Overall_Draft!O7 -> 3.9736441 | L5: =Overall_Draft!P7 -> 4 | M5: =Overall_Draft!Q7 -> 33.941633 | N5: =Overall_Draft!R7 -> 33.694863 | O5: =Overall_Draft!S7 -> 0.5885487 | ... S5: =Overall_Draft!W7 -> 0 | U5: =Overall_Draft!L39 -> Raghav Vista | V5: =Overall_Draft!M39 -> 0.4572421 | W5: =Overall_Draft!N39 -> 0.33286333 | X5: =Overall_Draft!O39 -> 0.7279805 | Y5: =Overall_Draft!P39 -> 0.46 | Z5: =Overall_Draft!Q39 -> 0.4936549 | AA5: =Overall_Draft!R39 -> 0.035090286 | AB5: =Overall_Draft!S39 -> 0.071082624 | ... AS5: =Overall_Draft!AJ39 -> 0.28 | AV5: =Overall!S23 -> Demand For Registrations post 20th of last month | AW5: =Overall!T23 -> 5.4110873 | AX5: =Overall!U23 -> 5.5059146 | AY5: =Overall!V23 -> 1.0175246 | AZ5: =Overall!W23 -> 5.41 | BA5: =Overall!X23 -> 0.0010873
B6: =Overall_Draft!L24 -> RAGHAV Avenue | C6: =Overall_Draft!M24 -> 4.9720375 | D6: =Overall_Draft!N24 -> 4.0402514 | E6: =IFERROR(D6/C6,"") -> 0.81259472 | F6: =Overall_Draft!P24 -> 4.17 | G6: =Overall_Draft!Q24 -> 0.12974859 | H6: =Overall_Draft!L8 -> RAGHAV Avenue | I6: =Overall_Draft!M8 -> 54 | J6: =Overall_Draft!N8 -> 0 | K6: =Overall_Draft!O8 -> 4.2654046 | L6: =Overall_Draft!P8 -> 7 | M6: =Overall_Draft!Q8 -> 23.986368 | N6: =Overall_Draft!R8 -> 24.688711 | O6: =Overall_Draft!S8 -> 2.6275068 | ... S6: =Overall_Draft!W8 -> 0 | U6: =Overall_Draft!L40 -> RAGHAV Avenue | V6: =Overall_Draft!M40 -> 0.4509504 | W6: =Overall_Draft!N40 -> 0.7862227 | X6: =Overall_Draft!O40 -> 1.7434793 | Y6: =Overall_Draft!P40 -> 0.16 | Z6: =Overall_Draft!Q40 -> 0.5620902 | AA6: =Overall_Draft!R40 -> 0.16809524 | AB6: =Overall_Draft!S40 -> 0.29905385 | ... AS6: =Overall_Draft!AJ40 -> 0.29 | AV6: =Overall!S24 -> Expected New Monthly Registrations | AW6: =Overall!T24 -> 13.69 | AX6: =Overall!U24 -> 6.7300527 | AY6: =Overall!V24 -> 0.49160356 | AZ6: =Overall!W24 -> 9.37 | BA6: =Overall!X24 -> 4.32
B7: =Overall_Draft!L25 -> RAGHAV UTOPIA | C7: =Overall_Draft!M25 -> 0 | D7: =Overall_Draft!N25 -> 0 | E7: =IFERROR(D7/C7,"") | F7: =Overall_Draft!P25 -> 0 | G7: =Overall_Draft!Q25 -> 0 | H7: =Overall_Draft!L9 -> RAGHAV UTOPIA | I7: =Overall_Draft!M9 -> 16 | J7: =Overall_Draft!N9 -> 0 | K7: =Overall_Draft!O9 -> 0.82010581 | L7: =Overall_Draft!P9 -> 2 | M7: =Overall_Draft!Q9 -> 1.3584535 | N7: =Overall_Draft!R9 -> 1.4807048 | O7: =Overall_Draft!S9 -> 0.4765766 | ... S7: =Overall_Draft!W9 -> 0 | U7: =Overall_Draft!L41 -> Raghav UTOPIA | V7: =Overall_Draft!M41 -> 0 | W7: =Overall_Draft!N41 -> 0 | X7: =Overall_Draft!O41 -> #DIV/0! | Y7: =Overall_Draft!P41 -> 0 | Z7: =Overall_Draft!Q41 -> 0.2687297 | AA7: =Overall_Draft!R41 -> 0.57619048 | AB7: =Overall_Draft!S41 -> 2.1441265 | ... AS7: =Overall_Draft!AJ41 -> 0 | AV7: =Overall!S25 -> New Slab / New Demand | AW7: =Overall!T25 -> 12.42 | AX7: =Overall!U25 -> 8.2525539 | AY7: =Overall!V25 -> 0.66445684 | AZ7: =Overall!W25 -> 0.57 | BA7: =Overall!X25 -> 11.85
B8: =Overall_Draft!L26 -> RAGHAV Enclave | C8: =Overall_Draft!M26 -> 4.2966186 | D8: =Overall_Draft!N26 -> 2.0216195 | E8: =IFERROR(D8/C8,"") -> 0.47051407 | F8: =Overall_Draft!P26 -> 4.3 | G8: =Overall_Draft!Q26 -> 2.2783805 | H8: =Overall_Draft!L10 -> RAGHAV Enclave | I8: =Overall_Draft!M10 -> 24 | J8: =Overall_Draft!N10 -> 0 | K8: =Overall_Draft!O10 -> 2.205519 | L8: =Overall_Draft!P10 -> 0 | M8: =Overall_Draft!Q10 -> 19.816488 | N8: =Overall_Draft!R10 -> 18.298131 | O8: =Overall_Draft!S10 -> 1.961495 | ... S8: =Overall_Draft!W10 -> 0 | U8: =Overall_Draft!L42 -> Raghav Enclave | V8: =Overall_Draft!M42 -> 1.8166184 | W8: =Overall_Draft!N42 -> 0.47619048 | X8: =Overall_Draft!O42 -> 0.26213016 | Y8: =Overall_Draft!P42 -> 1.82 | Z8: =Overall_Draft!Q42 -> 0.19 | AA8: =Overall_Draft!R42 -> 0.18389952 | AB8: =Overall_Draft!S42 -> 0.96789223 | ... AS8: =Overall_Draft!AJ42 -> 0
B9: =Overall_Draft!L27 -> Overall | C9: =Overall_Draft!M27 -> 44.918095 | D9: =Overall_Draft!N27 -> 27.527802 | E9: =IFERROR(D9/C9,"") -> 0.61284438 | F9: =Overall_Draft!P27 -> 22.59 | G9: =Overall_Draft!Q27 -> -4.9378017 | H9: =Overall_Draft!L11 -> Total | I9: =Overall_Draft!M11 -> 510 | J9: =Overall_Draft!N11 -> 0 | K9: =Overall_Draft!O11 -> 29.701636 | L9: =Overall_Draft!P11 -> 18 | M9: =Overall_Draft!Q11 -> 433.22012 | N9: =Overall_Draft!R11 -> 427.53806 | O9: =Overall_Draft!S11 -> 16.891745 | ... S9: =Overall_Draft!W11 -> 0 | U9: =Overall_Draft!L43 -> Overall | V9: =Overall_Draft!M43 -> 13.397007 | W9: =Overall_Draft!N43 -> 7.0392804 | X9: =Overall_Draft!O43 -> 0.52543679 | Y9: =Overall_Draft!P43 -> 7.24 | Z9: =Overall_Draft!Q43 -> 2.2067938 | AA9: =Overall_Draft!R43 -> 1.4775612 | AB9: =Overall_Draft!S43 -> 0.66955111 | ... AS9: =Overall_Draft!AJ43 -> 0.57
